<?xml version='1.0' encoding='utf-8'?>
<mujoco model="biped_s62">
  <compiler angle="radian" />
  <size njmax="500" nconmax="100" />

  <asset>
    <mesh name="base_link" file="../robots/kuavo_wheel_s62/meshes/base_link.STL"/>
    <mesh name="wheel_left_front" file="../robots/kuavo_wheel_s62/meshes/wheel_left_front.STL"/>
    <mesh name="wheel_right_front" file="../robots/kuavo_wheel_s62/meshes/wheel_right_front.STL"/>
    <mesh name="wheel_left_behind" file="../robots/kuavo_wheel_s62/meshes/wheel_left_behind.STL"/>
    <mesh name="wheel_right_behind" file="../robots/kuavo_wheel_s62/meshes/wheel_right_behind.STL"/>
    <mesh name="knee_link" file="../robots/kuavo_wheel_s62/meshes/knee_link.STL"/>
    <mesh name="leg_Link" file="../robots/kuavo_wheel_s62/meshes/leg_Link.STL"/>
    <mesh name="waist_pitch_Link" file="../robots/kuavo_wheel_s62/meshes/waist_pitch_Link.STL"/>
    <mesh name="waist_yaw_Link" file="../robots/kuavo_wheel_s62/meshes/waist_yaw_Link.STL"/>
    <mesh name="torso" file="../robots/kuavo_wheel_s62/meshes/torso.STL"/>
    <mesh name="l_arm_pitch" file="../robots/kuavo_wheel_s62/meshes/l_arm_pitch.STL"/>
    <mesh name="l_arm_roll" file="../robots/kuavo_wheel_s62/meshes/l_arm_roll.STL"/>
    <mesh name="l_arm_yaw" file="../robots/kuavo_wheel_s62/meshes/l_arm_yaw.STL"/>
    <mesh name="l_forearm" file="../robots/kuavo_wheel_s62/meshes/l_forearm.STL"/>
    <mesh name="l_hand_yaw" file="../robots/kuavo_wheel_s62/meshes/l_hand_yaw.STL"/>
    <mesh name="l_hand_roll" file="../robots/kuavo_wheel_s62/meshes/l_hand_roll.STL"/>
    <mesh name="l_hand_pitch_noHand" file="../robots/kuavo_wheel_s62/meshes/l_hand_pitch_noHand.STL"/>
    <mesh name="r_arm_pitch" file="../robots/kuavo_wheel_s62/meshes/r_arm_pitch.STL"/>
    <mesh name="r_arm_roll" file="../robots/kuavo_wheel_s62/meshes/r_arm_roll.STL"/>
    <mesh name="r_arm_yaw" file="../robots/kuavo_wheel_s62/meshes/r_arm_yaw.STL"/>
    <mesh name="r_forearm" file="../robots/kuavo_wheel_s62/meshes/r_forearm.STL"/>
    <mesh name="r_hand_yaw" file="../robots/kuavo_wheel_s62/meshes/r_hand_yaw.STL"/>
    <mesh name="r_hand_roll" file="../robots/kuavo_wheel_s62/meshes/r_hand_roll.STL"/>
    <mesh name="r_hand_pitch_noHand" file="../robots/kuavo_wheel_s62/meshes/r_hand_pitch_noHand.STL"/>
    <mesh name="r_f_bar-1" file="../robots/kuavo_wheel_s62/meshes/r_f_bar_1.STL"/>
    <mesh name="r_f_bar-2" file="../robots/kuavo_wheel_s62/meshes/r_f_bar-2.STL"/>
    <mesh name="r_f_bar-3" file="../robots/kuavo_wheel_s62/meshes/r_f_bar-3.STL"/>
    <mesh name="r_f_fingers" file="../robots/kuavo_wheel_s62/meshes/r_f_finger.STL"/>
    <mesh name="r_b_bar-1" file="../robots/kuavo_wheel_s62/meshes/r_b_bar-1.STL"/>
    <mesh name="r_b_bar-2" file="../robots/kuavo_wheel_s62/meshes/r_b_bar-2.STL"/>
    <mesh name="r_b_bar-3" file="../robots/kuavo_wheel_s62/meshes/r_b_bar-3.STL"/>
    <mesh name="r_b_fingers" file="../robots/kuavo_wheel_s62/meshes/r_b_fingers.STL"/>
    <mesh name="head_yaw" file="../robots/kuavo_wheel_s62/meshes/head_yaw.STL"/>
    <mesh name="head_pitch" file="../robots/kuavo_wheel_s62/meshes/head_pitch.STL"/>
    <mesh name="head_camera" file="../robots/kuavo_wheel_s62/meshes/head_camera.STL"/>
    <mesh name="head_radar" file="../robots/kuavo_wheel_s62/meshes/head_radar.STL"/>
  </asset>

  <worldbody>
    <body name="base_link" pos="0 0 0">
      <joint name="base_x_joint" type="slide" axis="1 0 0" damping="5"/>
      <joint name="base_y_joint" type="slide" axis="0 1 0" damping="5"/>
      <joint name="base_yaw_joint" type="hinge" axis="0 0 1" damping="2"/>
      <site name="imu" pos="0 0 0" />
      <inertial pos="0.00537945 -0.000630114 0.198965" quat="0.019647 0.695011 -0.0174445 0.718519" mass="400.275" diaginertia="9.46041 6.41364 6.2676"/>
      <geom type="mesh" contype="0" conaffinity="0" group="1" density="0" rgba="1 1 1 1" mesh="base_link"/>
      <geom pos="0.232489 0.232489 0.13035" quat="0.92388 0 0 0.382683" type="mesh" contype="0" conaffinity="0" group="1" density="0" rgba="1 1 1 1" mesh="wheel_left_front"/>
      <geom pos="0.232489 -0.232489 0.13035" quat="0.92388 0 0 -0.382683" type="mesh" contype="0" conaffinity="0" group="1" density="0" rgba="1 1 1 1" mesh="wheel_right_front"/>
      <geom pos="-0.232489 0.232489 0.13035" quat="0.382683 0 0 0.92388" type="mesh" contype="0" conaffinity="0" group="1" density="0" rgba="1 1 1 1" mesh="wheel_left_behind"/>
      <geom pos="-0.232489 -0.232489 0.13035" quat="0.382683 0 0 -0.92388" type="mesh" contype="0" conaffinity="0" group="1" density="0" rgba="1 1 1 1" mesh="wheel_right_behind"/>
      <geom pos="0.098 0 0.270643" type="mesh" contype="0" conaffinity="0" group="1" density="0" rgba="1 1 1 1" mesh="knee_link"/>
      <body name="LF_wheel_yaw" pos="0.232489 0.232489 0.13035">
        <inertial pos="0 0 0" mass="0.0001" diaginertia="0.0000001 0.0000001 0.0000001"/>
        <joint name="LF_wheel_yaw_joint" pos="0 0 0" axis="0 0 1" damping="5.0"/>
        <body name="LF_wheel_pitch">
          <inertial pos="0 0 0" mass="0.0001" diaginertia="0.0000001 0.0000001 0.0000001"/>
          <joint name="LF_wheel_pitch_joint" pos="0 0 0" axis="0 1 0" damping="0.2"/>
          <geom size="0.13035 0.015" quat="0.707107 0.707107 0 0" type="cylinder" rgba="1 1 1 0" friction="3.0 0.001 0.001"/>
        </body>
      </body>
      <body name="RF_wheel_yaw" pos="0.232489 -0.232489 0.13035">
        <inertial pos="0 0 0" mass="0.0001" diaginertia="0.0000001 0.0000001 0.0000001"/>
        <joint name="RF_wheel_yaw_joint" pos="0 0 0" axis="0 0 1" damping="5.0"/>
        <body name="RF_wheel_pitch">
          <inertial pos="0 0 0" mass="0.0001" diaginertia="0.0000001 0.0000001 0.0000001"/>
          <joint name="RF_wheel_pitch_joint" pos="0 0 0" axis="0 1 0" damping="0.2"/>
          <geom size="0.13035 0.015" quat="0.707107 0.707107 0 0" type="cylinder" rgba="1 1 1 0" friction="3.0 0.001 0.001"/>
        </body>
      </body>
      <body name="LB_wheel_yaw" pos="-0.232489 0.232489 0.13035">
        <inertial pos="0 0 0" mass="0.0001" diaginertia="0.0000001 0.0000001 0.0000001"/>
        <joint name="LB_wheel_yaw_joint" pos="0 0 0" axis="0 0 1" damping="5.0"/>
        <body name="LB_wheel_pitch">
          <inertial pos="0 0 0" mass="0.0001" diaginertia="0.0000001 0.0000001 0.0000001"/>
          <joint name="LB_wheel_pitch_joint" pos="0 0 0" axis="0 1 0" damping="0.2"/>
          <geom size="0.13035 0.015" quat="0.707107 0.707107 0 0" type="cylinder" rgba="1 1 1 0" friction="3.0 0.001 0.001"/>
        </body>
      </body>
      <body name="RB_wheel_yaw" pos="-0.232489 -0.232489 0.13035">
        <inertial pos="0 0 0" mass="0.0001" diaginertia="0.00000001 0.0000001 0.0000001"/>
        <joint name="RB_wheel_yaw_joint" pos="0 0 0" axis="0 0 1" damping="5.0"/>
        <body name="RB_wheel_pitch">
          <inertial pos="0 0 0" mass="0.0001" diaginertia="0.0000001 0.0000001 0.0000001"/>
          <joint name="RB_wheel_pitch_joint" pos="0 0 0" axis="0 1 0" damping="0.2"/>
          <geom size="0.13035 0.015" quat="0.707107 0.707107 0 0" type="cylinder" rgba="1 1 1 0" friction="3.0 0.001 0.001"/>
        </body>
      </body>
      <body name="knee_link" pos="0.098 0 0.376143">
        <inertial pos="-0.228954 0.00062518 0.0881745" quat="-0.0046512 0.823659 0.0121074 0.566937" mass="13.4136" diaginertia="0.488625 0.449931 0.0890849"/>
        <joint name="knee_joint" pos="0 0 0" axis="0 1 0" range="0 1.44862" actuatorfrcrange="-668.53 668.53" damping="8.0"/>
        <geom type="mesh" contype="0" conaffinity="0" group="1" density="0" rgba="1 1 1 1" mesh="leg_Link"/>
        <body name="leg_link" pos="-0.46521 0 0.18325">
          <inertial pos="0.247062 0.0113029 0.0677251" quat="0.57029 0.439766 0.420379 0.551957" mass="9.78118" diaginertia="0.390917 0.373424 0.0334399"/>
          <joint name="leg_joint" pos="0 0 0" axis="0 1 0" range="-2.80998 0" actuatorfrcrange="-668.53 668.53" damping="8.0"/>
          <geom type="mesh" contype="0" conaffinity="0" group="1" density="0" rgba="1 1 1 1" mesh="waist_pitch_Link"/>
          <body name="waist_pitch_link" pos="0.48296 0 0.12941">
            <inertial pos="-0.00148154 0 0.0584625" quat="0.707107 0.707107 0 0" mass="4.65998" diaginertia="0.047446 0.0387095 0.0364961"/>
            <joint name="waist_pitch_joint" pos="0 0 0" axis="0 1 0" range="-0.15708 2.98451" actuatorfrcrange="-618.48 618.48" damping="10.0"/>
            <geom type="mesh" contype="0" conaffinity="0" group="1" density="0" rgba="1 1 1 1" mesh="waist_yaw_Link"/>
            <body name="waist_yaw_link" pos="0 0 0.235">
              <inertial pos="0.00159298 -0.00027078 0.131874" mass="11.5609" diaginertia="0.246636 0.159377 0.158813"/>
              <joint name="waist_yaw_joint" pos="0 0 0" axis="0 0 1" range="-3.14159 3.14159" actuatorfrcrange="-618.48 618.48" damping="6.0"/>
              <geom type="mesh" contype="0" conaffinity="0" group="1" density="0" rgba="1 1 1 1" mesh="torso"/>
              <body name="zarm_l1_link" pos="0 0.2527 0.242">
                <inertial pos="0.00166796 -0.008241 0.00012987" quat="0.707107 0.707107 0 0" mass="0.916533" diaginertia="0.00126587 0.00124337 0.00086921"/>
                <joint name="zarm_l1_joint" pos="0 0 0" axis="0 1 0" range="-3.14159 1.5708" actuatorfrcrange="-85 85" damping="2.0"/>
                <geom pos="0 -0.081 0" quat="1 0 0 0" type="mesh" contype="0" conaffinity="0" group="1" density="0" rgba="1 1 1 1" mesh="l_arm_pitch"/>
                <body name="zarm_l2_link">
                  <inertial pos="-0.00080994 4.86e-06 -0.0465103" quat="0.707107 0 0 0.707107" mass="0.387674" diaginertia="0.00116144 0.00080739 0.00070223"/>
                  <joint name="zarm_l2_joint" pos="0 0 0" axis="1 0 0" range="-0.349066 3.49066" actuatorfrcrange="-75 75" damping="2.0"/>
                  <geom type="mesh" contype="0" conaffinity="0" group="1" density="0" rgba="1 1 1 1" mesh="l_arm_roll"/>
                  <body name="zarm_l3_link">
                    <inertial pos="0.00943019 0.00343988 -0.113045" quat="0.707107 0 0 0.707107" mass="1.77927" diaginertia="0.0100458 0.00992856 0.00185422"/>
                    <joint name="zarm_l3_joint" pos="0 0 0" axis="0 0 1" range="-1.48353 1.48353" actuatorfrcrange="-57 57" damping="1.6"/>
                    <geom type="mesh" contype="0" conaffinity="0" group="1" density="0" rgba="1 1 1 1" mesh="l_arm_yaw"/>
                    <body name="zarm_l4_link" pos="0.02 0 -0.2837">
                      <inertial pos="-0.0182993 0.00087167 -0.0693662" mass="0.585078" diaginertia="0.00143291 0.00125018 0.00068356"/>
                      <joint name="zarm_l4_joint" pos="0 0 0" axis="0 1 0" range="-2.61799 0" actuatorfrcrange="-75 75" damping="2.0"/>
                      <geom type="mesh" contype="0" conaffinity="0" group="1" density="0" rgba="1 1 1 1" mesh="l_forearm"/>
                      <body name="zarm_l5_link" pos="-0.02 0 -0.1195">
                        <inertial pos="0.0002609 1.322e-05 -0.0608394" quat="0.707107 0 0 0.707107" mass="0.6868" diaginertia="0.00122518 0.00086873 0.00066873"/>
                        <joint name="zarm_l5_joint" pos="0 0 0" axis="0 0 1" range="-1.5708 1.5708" actuatorfrcrange="-14.1 14.1" damping="0.8"/>
                        <geom type="mesh" contype="0" conaffinity="0" group="1" density="0" rgba="1 1 1 1" mesh="l_hand_yaw"/>
                        <body name="zarm_l6_link" pos="0 0 -0.114">
                          <inertial pos="0.00019162 0 -0.0174775" quat="0 0.707107 0 0.707107" mass="0.393872" diaginertia="0.0002021 0.00019853 0.00018535"/>
                          <joint name="zarm_l6_joint" pos="0 0 0" axis="1 0 0" range="-1.309 0.698132" actuatorfrcrange="-14.1 14.1" damping="0.8"/>
                          <geom type="mesh" contype="0" conaffinity="0" group="1" density="0" rgba="1 1 1 1" mesh="l_hand_roll"/>
                          <body name="zarm_l7_link" pos="0 0 -0.021">
                            <inertial pos="0 0 -0.102359" quat="0.707107 0 0 0.707107" mass="0.715902" diaginertia="0.00106704 0.00106284 0.00106143"/>
                            <joint name="zarm_l7_joint" pos="0 0 0" axis="0 1 0" range="-0.698132 0.698132" actuatorfrcrange="-14.1 14.1" damping="0.8"/>
                            <geom type="mesh" contype="0" conaffinity="0" group="1" density="0" rgba="1 1 1 1" mesh="l_hand_pitch_noHand"/>
                            <geom size="0.005" pos="0 0 -0.17"/>
                            <body name="zarm_l7_end_effector" pos="0 0 -0.17">
                              <site name="l_arm_ft_frame" pos="0 0 0" size="0.01 0.005 0.01" rgba="1 0 0 1" type="box" group="1"/>
                              <geom type="box" size="0.01 0.005 0.02" contype="1" conaffinity="1"/>
                            </body>
                          </body>
                        </body>
                      </body>
                    </body>
                  </body>
                </body>
              </body>
              <body name="zarm_r1_link" pos="0 -0.2527 0.242">
                <inertial pos="-0.00166796 0.00839971 0.00012987" quat="0.707107 0.707107 0 0" mass="0.916533" diaginertia="0.00126587 0.00124337 0.00086921"/>
                <joint name="zarm_r1_joint" pos="0 0 0" axis="0 1 0" range="-3.14159 1.5708" actuatorfrcrange="-85 85" damping="2.0"/>
                <geom pos="0 0.081 0" quat="1 0 0 0" type="mesh" contype="0" conaffinity="0" group="1" density="0" rgba="1 1 1 1" mesh="r_arm_pitch"/>
                <body name="zarm_r2_link">
                  <inertial pos="-0.00080994 -4.86e-06 -0.0465103" quat="0.707107 0 0 0.707107" mass="0.387674" diaginertia="0.00116144 0.00080739 0.00070223"/>
                  <joint name="zarm_r2_joint" pos="0 0 0" axis="1 0 0" range="-3.49066 0.349066" actuatorfrcrange="-75 75" damping="2.0"/>
                  <geom type="mesh" contype="0" conaffinity="0" group="1" density="0" rgba="1 1 1 1" mesh="r_arm_roll"/>
                  <body name="zarm_r3_link">
                    <inertial pos="0.00943019 -0.00343988 -0.113045" quat="0.707107 0 0 0.707107" mass="1.77927" diaginertia="0.0100458 0.00992856 0.00185422"/>
                    <joint name="zarm_r3_joint" pos="0 0 0" axis="0 0 1" range="-1.48353 1.48353" actuatorfrcrange="-57 57" damping="1.6"/>
                    <geom type="mesh" contype="0" conaffinity="0" group="1" density="0" rgba="1 1 1 1" mesh="r_arm_yaw"/>
                    <body name="zarm_r4_link" pos="0.02 0 -0.2837">
                      <inertial pos="-0.0182993 -0.00087167 -0.0693662" mass="0.585078" diaginertia="0.00143291 0.00125018 0.00068356"/>
                      <joint name="zarm_r4_joint" pos="0 0 0" axis="0 1 0" range="-2.61799 0" actuatorfrcrange="-75 75" damping="2.0"/>
                      <geom type="mesh" contype="0" conaffinity="0" group="1" density="0" rgba="1 1 1 1" mesh="r_forearm"/>
                      <body name="zarm_r5_link" pos="-0.02 0 -0.1195">
                        <inertial pos="-0.0002609 1.322e-05 -0.0608394" quat="0.707107 0 0 0.707107" mass="0.6868" diaginertia="0.00122518 0.00086873 0.00066873"/>
                        <joint name="zarm_r5_joint" pos="0 0 0" axis="0 0 1" range="-1.5708 1.5708" actuatorfrcrange="-14.1 14.1" damping="0.8"/>
                        <geom type="mesh" contype="0" conaffinity="0" group="1" density="0" rgba="1 1 1 1" mesh="r_hand_yaw"/>
                        <body name="zarm_r6_link" pos="0 0 -0.114">
                          <inertial pos="0.00019162 0 -0.0174775" quat="0 0.707107 0 0.707107" mass="0.393872" diaginertia="0.0002021 0.00019853 0.00018535"/>
                          <joint name="zarm_r6_joint" pos="0 0 0" axis="1 0 0" range="-0.698132 1.309" actuatorfrcrange="-14.1 14.1" damping="0.8"/>
                          <geom type="mesh" contype="0" conaffinity="0" group="1" density="0" rgba="1 1 1 1" mesh="r_hand_roll"/>
                          <body name="zarm_r7_link" pos="0 0 -0.021">
                            <inertial pos="0 0 -0.102359" quat="0.707107 0 0 0.707107" mass="0.715902" diaginertia="0.00106704 0.00106284 0.00106143"/>
                            <joint name="zarm_r7_joint" pos="0 0 0" axis="0 1 0" range="-0.698132 0.698132" actuatorfrcrange="-14.1 14.1" damping="0.8"/>
                            <!-- Legacy right-hand geometry removed: the official LejuClaw
                                 below is mounted at the original right end-effector frame. -->
                            <!-- 右手末端执行器 -->
                            <geom type="mesh" contype="0" conaffinity="0" group="1" density="0" rgba="1 1 1 1" mesh="r_hand_pitch_noHand"/>
                            <body name="zarm_r7_end_effector" pos="0 0 -0.11">
                              <site name="r_arm_ft_frame" pos="0 0 0" size="0.01 0.005 0.01" rgba="0 0 1 1" type="box" group="1"/>
                              <geom type="box" size="0.01 0.005 0.02" contype="0" conaffinity="0"/>
                              <body name="r_pinch" pos="0 -0.0005 -0.0772">
                                <site name="r_pinch_site" pos="0 0 0" size="0.01" rgba="0 1 1 1"/>
                              </body>
                              <body name="r_f_bar-1" pos="0.022 -0.0005 -0.0014">
                                <inertial pos="0.00725282 0.0000073 -0.0105238" mass="0.00947618" diaginertia="0.00000255 0.00000245 0.00000069"/>
                                <joint name="r_f_bar-1" pos="0 0 0" axis="0 1 0" range="-0.698 0.698" damping="0.05"/>
                                <geom type="mesh" rgba="1 1 1 1" mesh="r_f_bar-1" contype="0" conaffinity="0"/>
                                <body name="r_f_bar-2" pos="0.0254381 0 -0.0464963">
                                  <inertial pos="-0.00783156 0 -0.0147534" mass="0.00339831" diaginertia="0.00000054 0.00000044 0.00000015"/>
                                  <joint name="r_f_bar-2" pos="0 0 0" axis="0 1 0" range="-0.698 0.698" damping="0.03"/>
                                  <geom type="mesh" rgba="1 1 1 1" mesh="r_f_bar-2" contype="0" conaffinity="0"/>
                                  <body name="r_f_fingers" pos="-0.0191549 0 -0.0292932">
                                    <inertial pos="-0.0155126 -0.0000091 -0.0133067" mass="0.00951656" diaginertia="0.00000130 0.00000116 0.00000046"/>
                                    <joint name="r_f_fingers" pos="0 0 0" axis="0 1 0" range="-0.698 0.698" damping="0.03"/>
                                    <geom type="mesh" rgba="1 1 1 1" mesh="r_f_fingers" contype="0" conaffinity="0"/>
                                    <geom name="r_f_fingers_pad" type="box" pos="-0.012 0 -0.012" size="0.014 0.007 0.024" rgba="0.04 0.04 0.04 1" contype="1" conaffinity="1" condim="4" friction="2.8 0.01 0.0001"/>
                                    <body name="r_f_fingers_end" pos="-0.0105 0 0.002"/>
                                  </body>
                                </body>
                              </body>
                              <body name="r_f_bar-3" pos="0.0239579 -0.0005 -0.025272">
                                <inertial pos="-0.00168674 -0.0000551 -0.0272296" mass="0.00913148" diaginertia="0.00000213 0.00000160 0.00000066"/>
                                <joint name="r_f_bar-3" pos="0 0 0" axis="0 1 0" range="-0.698 0.698" damping="0.03"/>
                                <geom type="mesh" rgba="1 1 1 1" mesh="r_f_bar-3" contype="0" conaffinity="0"/>
                                <body name="r_f_bar-3_end" pos="-0.00618 0 -0.05"/>
                              </body>
                              <body name="r_b_bar-1" pos="-0.022 -0.0005 -0.0014">
                                <inertial pos="-0.00725282 -0.0000073 -0.0105238" mass="0.00947618" diaginertia="0.00000255 0.00000245 0.00000069"/>
                                <joint name="r_b_bar-1" pos="0 0 0" axis="0 -1 0" range="-0.698 0.698" damping="0.05"/>
                                <geom type="mesh" rgba="1 1 1 1" mesh="r_b_bar-1" contype="0" conaffinity="0"/>
                                <body name="r_b_bar-2" pos="-0.0254381 0 -0.0464963">
                                  <inertial pos="0.00783156 0 -0.0147534" mass="0.00339831" diaginertia="0.00000054 0.00000044 0.00000015"/>
                                  <joint name="r_b_bar-2" pos="0 0 0" axis="0 -1 0" range="-0.698 0.698" damping="0.03"/>
                                  <geom type="mesh" rgba="1 1 1 1" mesh="r_b_bar-2" contype="0" conaffinity="0"/>
                                  <body name="r_b_fingers" pos="0.0191549 0 -0.0292932">
                                    <inertial pos="0.0155126 0.0000091 -0.0133067" mass="0.00951656" diaginertia="0.00000130 0.00000116 0.00000046"/>
                                    <joint name="r_b_fingers" pos="0 0 0" axis="0 -1 0" range="-0.698 0.698" damping="0.03"/>
                                    <geom type="mesh" rgba="1 1 1 1" mesh="r_b_fingers" contype="0" conaffinity="0"/>
                                    <geom name="r_b_fingers_pad" type="box" pos="0.012 0 -0.012" size="0.014 0.007 0.024" rgba="0.04 0.04 0.04 1" contype="1" conaffinity="1" condim="4" friction="2.8 0.01 0.0001"/>
                                    <body name="r_b_fingers_end" pos="0.0105 0 0.002"/>
                                  </body>
                                </body>
                              </body>
                              <body name="r_b_bar-3" pos="-0.0239579 0 -0.025272">
                                <inertial pos="0.00168674 0.0005551 -0.0272296" mass="0.00913148" diaginertia="0.00000213 0.00000160 0.00000066"/>
                                <joint name="r_b_bar-3" pos="0 0 0" axis="0 -1 0" range="-0.698 0.698" damping="0.03"/>
                                <geom type="mesh" rgba="1 1 1 1" mesh="r_b_bar-3" contype="0" conaffinity="0"/>
                                <body name="r_b_bar-3_end" pos="0.00618 0 -0.05"/>
                              </body>
                            </body>
                          </body>
                        </body>
                      </body>
                    </body>
                  </body>
                </body>
              </body>
              <body name="zhead_1_link" pos="0 0 0.3164">
                <inertial pos="0.00173082 -0.0033509 0.0948508" quat="1 4.68903e-05 2.29385e-05 4.13671e-05" mass="0.836974" diaginertia="0.00192825 0.00185813 0.000600654"/>
                <joint name="zhead_1_joint" pos="0 0 0" axis="0 0 1" range="-1.57 1.57" actuatorfrcrange="-15.5 15.5" damping="0.0"/>
                <geom type="mesh" contype="0" conaffinity="0" group="1" density="0" rgba="1 1 1 1" mesh="head_yaw"/>
                <geom pos="0 0 0.059701" quat="1 0 0 0" type="mesh" contype="0" conaffinity="0" group="1" density="0" rgba="0.611765 0.658824 0.670588 1" mesh="head_radar"/>
                <body name="zhead_2_link" pos="0 0 0.13795">
                  <inertial pos="0.030745 -0.00383958 0.0356665" quat="0.0350967 0.715721 -0.0948585 0.691023" mass="0.851207" diaginertia="0.00556572 0.00531893 0.00393134"/>
                  <joint name="zhead_2_joint" pos="0 0 0" axis="0 1 0" range="-0.526 0.526" actuatorfrcrange="-14.5 14.5" damping="0.0"/>
                  <geom type="mesh" contype="0" conaffinity="0" group="1" density="0" rgba="1 1 1 1" mesh="head_pitch"/>
                  <geom pos="0.099478 0 0.032897" quat="0.984018 0 0.17807 0" type="mesh" contype="0" conaffinity="0" group="1" density="0" rgba="1 1 1 1" mesh="head_camera"/>
                  <camera name="camera_rgb" pos="0.12 0 0.035" quat="0.623886757 0.282317910 -0.301056731 -0.663646560" fovy="58"/>
                </body>
              </body>
            </body>
          </body>
        </body>
      </body>
    </body>
  </worldbody>

  <contact>
    <exclude name="r_claw_e0" body1="r_f_bar-3" body2="r_f_fingers"/>
    <exclude name="r_claw_e1" body1="r_f_bar-2" body2="r_f_fingers"/>
    <exclude name="r_claw_e2" body1="r_f_bar-1" body2="r_f_fingers"/>
    <exclude name="r_claw_e3" body1="r_f_bar-1" body2="r_f_bar-2"/>
    <exclude name="r_claw_e4" body1="r_f_bar-2" body2="r_f_bar-3"/>
    <exclude name="r_claw_e5" body1="r_f_bar-3" body2="r_f_bar-1"/>
    <exclude name="r_claw_e6" body1="r_b_bar-3" body2="r_b_fingers"/>
    <exclude name="r_claw_e7" body1="r_b_bar-2" body2="r_b_fingers"/>
    <exclude name="r_claw_e8" body1="r_b_bar-1" body2="r_b_fingers"/>
    <exclude name="r_claw_e9" body1="r_b_bar-1" body2="r_b_bar-2"/>
    <exclude name="r_claw_e10" body1="r_b_bar-2" body2="r_b_bar-3"/>
    <exclude name="r_claw_e11" body1="r_b_bar-3" body2="r_b_bar-1"/>
  </contact>

  <equality>
    <weld name="r_claw_front_loop" body1="r_f_fingers_end" body2="r_f_bar-3_end" torquescale="0" solref="1e-4 1" solimp=".9999 .9999 .01"/>
    <weld name="r_claw_back_loop" body1="r_b_fingers_end" body2="r_b_bar-3_end" torquescale="0" solref="1e-4 1" solimp=".9999 .9999 .01"/>
    <joint name="r_claw_fb_sync" joint1="r_f_bar-1" joint2="r_b_bar-1" polycoef="0 1 0 0 0" solref="1e-4 1" solimp=".99 .99 .01"/>
    <joint name="r_claw_front_bar_sync" joint1="r_f_bar-1" joint2="r_f_bar-2" polycoef="0 1 0 0 0" solref="1e-2 1" solimp=".99 .99 .01"/>
    <joint name="r_claw_front_finger_sync" joint1="r_f_bar-1" joint2="r_f_fingers" polycoef="0 -1 0 0 0" solref="1e-2 1" solimp=".99 .99 .01"/>
    <joint name="r_claw_back_bar_sync" joint1="r_b_bar-1" joint2="r_b_bar-2" polycoef="0 1 0 0 0" solref="1e-2 1" solimp=".99 .99 .01"/>
    <joint name="r_claw_back_finger_sync" joint1="r_b_bar-1" joint2="r_b_fingers" polycoef="0 -1 0 0 0" solref="1e-2 1" solimp=".99 .99 .01"/>
  </equality>

  <tendon>
    <fixed name="r_claw_split">
      <joint joint="r_f_bar-1" coef="0.5"/>
      <joint joint="r_b_bar-1" coef="0.5"/>
    </fixed>
  </tendon>

  <actuator>
    <motor gear="1" joint="base_x_joint" name="base_x_motor" ctrllimited="true" ctrlrange="-1800 1800"/>
    <motor gear="1" joint="base_y_joint" name="base_y_motor" ctrllimited="true" ctrlrange="-1800 1800"/>
    <motor gear="1" joint="base_yaw_joint" name="base_yaw_motor" ctrllimited="true" ctrlrange="-1200 1200"/>

    <position joint="LF_wheel_yaw_joint" name="LF_wheel_yaw_joint_motor" kp="0.2" ctrllimited="true" ctrlrange="-3.14159 3.14159" />
    <motor gear="0.2" joint="LF_wheel_pitch_joint" name="LF_wheel_pitch_joint_motor" ctrllimited="true" ctrlrange="-3 3"  />
    <position joint="RF_wheel_yaw_joint" name="RF_wheel_yaw_joint_motor" kp="0.2" ctrllimited="true" ctrlrange="-3.14159 3.14159" />
    <motor gear="0.2" joint="RF_wheel_pitch_joint" name="RF_wheel_pitch_joint_motor" ctrllimited="true" ctrlrange="-3 3"  />
    <position joint="LB_wheel_yaw_joint" name="LB_wheel_yaw_joint_motor" kp="0.2" ctrllimited="true" ctrlrange="-3.14159 3.14159" />
    <motor gear="0.2" joint="LB_wheel_pitch_joint" name="LB_wheel_pitch_joint_motor" ctrllimited="true" ctrlrange="-3 3"  />
    <position joint="RB_wheel_yaw_joint" name="RB_wheel_yaw_joint_motor" kp="0.2" ctrllimited="true" ctrlrange="-3.14159 3.14159" />
    <motor gear="0.2" joint="RB_wheel_pitch_joint" name="RB_wheel_pitch_joint_motor" ctrllimited="true" ctrlrange="-3 3"  />

    <position joint="knee_joint" name="knee_joint_motor" kp="650" ctrllimited="true" ctrlrange="0 1.44862" />
    <position joint="leg_joint" name="leg_joint_motor" kp="650" ctrllimited="true" ctrlrange="-2.80998 0" />
    <position joint="waist_pitch_joint" name="waist_pitch_joint_motor" kp="850" ctrllimited="true" ctrlrange="-0.15708 2.98451" />
    <position joint="waist_yaw_joint" name="waist_yaw_joint_motor" kp="500" ctrllimited="true" ctrlrange="-3.14159 3.14159" />
    <position joint="zarm_l1_joint" name="zarm_l1_joint_motor" kp="420" ctrllimited="true" ctrlrange="-3.14159 1.5708" />
    <position joint="zarm_l2_joint" name="zarm_l2_joint_motor" kp="380" ctrllimited="true" ctrlrange="-0.349066 3.49066" />
    <position joint="zarm_l3_joint" name="zarm_l3_joint_motor" kp="320" ctrllimited="true" ctrlrange="-1.48353 1.48353" />
    <position joint="zarm_l4_joint" name="zarm_l4_joint_motor" kp="380" ctrllimited="true" ctrlrange="-2.61799 0" />
    <position joint="zarm_l5_joint" name="zarm_l5_joint_motor" kp="180" ctrllimited="true" ctrlrange="-1.5708 1.5708" />
    <position joint="zarm_l6_joint" name="zarm_l6_joint_motor" kp="180" ctrllimited="true" ctrlrange="-1.309 0.698132" />
    <position joint="zarm_l7_joint" name="zarm_l7_joint_motor" kp="180" ctrllimited="true" ctrlrange="-0.698132 0.698132" />
    <position joint="zarm_r1_joint" name="zarm_r1_joint_motor" kp="420" ctrllimited="true" ctrlrange="-3.14159 1.5708" />
    <position joint="zarm_r2_joint" name="zarm_r2_joint_motor" kp="380" ctrllimited="true" ctrlrange="-3.49066 0.349066" />
    <position joint="zarm_r3_joint" name="zarm_r3_joint_motor" kp="320" ctrllimited="true" ctrlrange="-1.48353 1.48353" />
    <position joint="zarm_r4_joint" name="zarm_r4_joint_motor" kp="380" ctrllimited="true" ctrlrange="-2.61799 0" />
    <position joint="zarm_r5_joint" name="zarm_r5_joint_motor" kp="180" ctrllimited="true" ctrlrange="-1.5708 1.5708" />
    <position joint="zarm_r6_joint" name="zarm_r6_joint_motor" kp="180" ctrllimited="true" ctrlrange="-0.698132 1.309" />
    <position joint="zarm_r7_joint" name="zarm_r7_joint_motor" kp="180" ctrllimited="true" ctrlrange="-0.698132 0.698132" />
    <position joint="zhead_1_joint" name="zhead_1_joint_motor" kp="45" ctrllimited="true" ctrlrange="-1.57 1.57" />
    <position joint="zhead_2_joint" name="zhead_2_joint_motor" kp="45" ctrllimited="true" ctrlrange="-0.526 0.526" />
    <general biastype="affine" name="r_fingers_actuator" tendon="r_claw_split" forcerange="-100 100" ctrlrange="-100 0" gainprm="1 0 0" biasprm="0 -100 -5"/>
  </actuator>
  <sensor>
    <accelerometer name="BodyAcc" site="imu" />
    <velocimeter name="BodyVel" site="imu" />
    <gyro name="BodyGyro" site="imu" />
    <framepos name="BodyPos" objtype="site" objname="imu" />
    <framequat name="BodyQuat" objtype="site" objname="imu" />
    <force name="l_arm_force" site="l_arm_ft_frame"/>
    <torque name="l_arm_torque" site="l_arm_ft_frame"/>
    <force name="r_arm_force" site="r_arm_ft_frame"/>
    <torque name="r_arm_torque" site="r_arm_ft_frame"/>

    <jointpos name="LF_wheel_yaw_joint_pos"   joint="LF_wheel_yaw_joint"   />
    <jointpos name="LF_wheel_pitch_joint_pos" joint="LF_wheel_pitch_joint" />
    <jointpos name="RF_wheel_yaw_joint_pos"   joint="RF_wheel_yaw_joint"   />
    <jointpos name="RF_wheel_pitch_joint_pos" joint="RF_wheel_pitch_joint" />
    <jointpos name="LB_wheel_yaw_joint_pos"   joint="LB_wheel_yaw_joint"   />
    <jointpos name="LB_wheel_pitch_joint_pos" joint="LB_wheel_pitch_joint" />
    <jointpos name="RB_wheel_yaw_joint_pos"   joint="RB_wheel_yaw_joint"   />
    <jointpos name="RB_wheel_pitch_joint_pos" joint="RB_wheel_pitch_joint" />

    <jointpos name="knee_joint_pos" joint="knee_joint" />
    <jointpos name="leg_joint_pos" joint="leg_joint" />
    <jointpos name="waist_pitch_joint_pos" joint="waist_pitch_joint" />
    <jointpos name="waist_yaw_joint_pos" joint="waist_yaw_joint" />
    <jointpos name="zarm_l1_joint_pos" joint="zarm_l1_joint" />
    <jointpos name="zarm_l2_joint_pos" joint="zarm_l2_joint" />
    <jointpos name="zarm_l3_joint_pos" joint="zarm_l3_joint" />
    <jointpos name="zarm_l4_joint_pos" joint="zarm_l4_joint" />
    <jointpos name="zarm_l5_joint_pos" joint="zarm_l5_joint" />
    <jointpos name="zarm_l6_joint_pos" joint="zarm_l6_joint" />
    <jointpos name="zarm_l7_joint_pos" joint="zarm_l7_joint" />
    <jointpos name="zarm_r1_joint_pos" joint="zarm_r1_joint" />
    <jointpos name="zarm_r2_joint_pos" joint="zarm_r2_joint" />
    <jointpos name="zarm_r3_joint_pos" joint="zarm_r3_joint" />
    <jointpos name="zarm_r4_joint_pos" joint="zarm_r4_joint" />
    <jointpos name="zarm_r5_joint_pos" joint="zarm_r5_joint" />
    <jointpos name="zarm_r6_joint_pos" joint="zarm_r6_joint" />
    <jointpos name="zarm_r7_joint_pos" joint="zarm_r7_joint" />
    <jointpos name="zhead_1_joint_pos" joint="zhead_1_joint" />
    <jointpos name="zhead_2_joint_pos" joint="zhead_2_joint" />

    <jointvel name="LF_wheel_yaw_joint_vel"   joint="LF_wheel_yaw_joint"   />
    <jointvel name="LF_wheel_pitch_joint_vel" joint="LF_wheel_pitch_joint" />
    <jointvel name="RF_wheel_yaw_joint_vel"   joint="RF_wheel_yaw_joint"   />
    <jointvel name="RF_wheel_pitch_joint_vel" joint="RF_wheel_pitch_joint" />
    <jointvel name="LB_wheel_yaw_joint_vel"   joint="LB_wheel_yaw_joint"   />
    <jointvel name="LB_wheel_pitch_joint_vel" joint="LB_wheel_pitch_joint" />
    <jointvel name="RB_wheel_yaw_joint_vel"   joint="RB_wheel_yaw_joint"   />
    <jointvel name="RB_wheel_pitch_joint_vel" joint="RB_wheel_pitch_joint" />

    <jointvel name="knee_joint_vel" joint="knee_joint" />
    <jointvel name="leg_joint_vel" joint="leg_joint" />
    <jointvel name="waist_pitch_joint_vel" joint="waist_pitch_joint" />
    <jointvel name="waist_yaw_joint_vel" joint="waist_yaw_joint" />
    <jointvel name="zarm_l1_joint_vel" joint="zarm_l1_joint" />
    <jointvel name="zarm_l2_joint_vel" joint="zarm_l2_joint" />
    <jointvel name="zarm_l3_joint_vel" joint="zarm_l3_joint" />
    <jointvel name="zarm_l4_joint_vel" joint="zarm_l4_joint" />
    <jointvel name="zarm_l5_joint_vel" joint="zarm_l5_joint" />
    <jointvel name="zarm_l6_joint_vel" joint="zarm_l6_joint" />
    <jointvel name="zarm_l7_joint_vel" joint="zarm_l7_joint" />
    <jointvel name="zarm_r1_joint_vel" joint="zarm_r1_joint" />
    <jointvel name="zarm_r2_joint_vel" joint="zarm_r2_joint" />
    <jointvel name="zarm_r3_joint_vel" joint="zarm_r3_joint" />
    <jointvel name="zarm_r4_joint_vel" joint="zarm_r4_joint" />
    <jointvel name="zarm_r5_joint_vel" joint="zarm_r5_joint" />
    <jointvel name="zarm_r6_joint_vel" joint="zarm_r6_joint" />
    <jointvel name="zarm_r7_joint_vel" joint="zarm_r7_joint" />
    <jointvel name="zhead_1_joint_vel" joint="zhead_1_joint" />
    <jointvel name="zhead_2_joint_vel" joint="zhead_2_joint" />
  </sensor>
</mujoco>
